<sdf version='1.11'>
  <model name='limo_ackerman'>
    <link name='base_footprint'>
      <inertial>
        <pose>0.007904637105296531 0 0.14940820898676921 0 0 0</pose>
        <mass>2.3656999999999999</mass>
        <inertia>
          <ixx>0.24030687149258151</ixx>
          <ixy>0</ixy>
          <ixz>8.7133508052584466e-05</ixz>
          <iyy>0.96192555477871244</iyy>
          <iyz>0</iyz>
          <izz>0.96162078328613076</izz>
        </inertia>
      </inertial>
      <collision name='base_footprint_fixed_joint_lump__base_link_collision'>
        <pose>0 0 0.14999999999999999 0 0 0</pose>
        <geometry>
          <box>
            <size>0.13 0.12 0.10000000000000001</size>
          </box>
        </geometry>
        <surface>
          <contact>
            <ode>
              <kp>10000000</kp>
              <kd>1</kd>
              <min_depth>0.001</min_depth>
            </ode>
          </contact>
          <friction>
            <ode/>
          </friction>
        </surface>
      </collision>
      <collision name='base_footprint_fixed_joint_lump__depth_camera_collision_collision_1'>
        <pose>0.084000000000000005 0 0.17999999999999999 0 0 0</pose>
        <geometry>
          <box>
            <size>0.02 0.059999999999999998 0.014999999999999999</size>
          </box>
        </geometry>
      </collision>
      <collision name='base_footprint_fixed_joint_lump__imu_collision_collision_2'>
        <pose>0 0 0.049999999999999989 0 0 0</pose>
        <geometry>
          <box>
            <size>0.001 0.001 0.001</size>
          </box>
        </geometry>
      </collision>
      <collision name='base_footprint_fixed_joint_lump__laser_collision_collision_3'>
        <pose>0.10299999999999999 0 0.11600000000000001 0 0 0</pose>
        <geometry>
          <cylinder>
            <length>0.016</length>
            <radius>0.032000000000000001</radius>
          </cylinder>
        </geometry>
      </collision>
      <visual name='base_footprint_fixed_joint_lump__base_link_visual'>
        <pose>0 0 0 0 0 1.5700000000000001</pose>
        <geometry>
          <mesh>
            <scale>1 1 1</scale>
            <uri>model://limo_description/meshes/limo_base.dae</uri>
          </mesh>
        </geometry>
      </visual>
      <visual name='base_footprint_fixed_joint_lump__depth_camera_visual_visual_1'>
        <pose>0.084000000000000005 0 0.17999999999999999 0 0 0</pose>
        <geometry>
          <box>
            <size>0.02 0.059999999999999998 0.014999999999999999</size>
          </box>
        </geometry>
        <material>
          <diffuse>0.125 0.125 0.25 1</diffuse>
          <ambient>0.125 0.125 0.25 1</ambient>
        </material>
      </visual>
      <visual name='base_footprint_fixed_joint_lump__imu_visual_visual_2'>
        <pose>0 0 0.049999999999999989 0 0 0</pose>
        <geometry>
          <box>
            <size>0.001 0.001 0.001</size>
          </box>
        </geometry>
        <material>
          <diffuse>0.125 0.125 0.25 1</diffuse>
          <ambient>0.125 0.125 0.25 1</ambient>
        </material>
      </visual>
      <visual name='base_footprint_fixed_joint_lump__laser_visual_visual_3'>
        <pose>0.10299999999999999 0 0.11600000000000001 0 0 0</pose>
        <geometry>
          <cylinder>
            <length>0.01</length>
            <radius>0.02</radius>
          </cylinder>
        </geometry>
        <material>
          <diffuse>0.125 0.125 0.25 1</diffuse>
          <ambient>0.125 0.125 0.25 1</ambient>
        </material>
      </visual>
      <sensor name='sensor_camera' type='depth'>
        <always_on>true</always_on>
        <visualize>true</visualize>
        <update_rate>10</update_rate>
        <camera name='head'>
          <horizontal_fov>1.3962634</horizontal_fov>
          <image>
            <width>640</width>
            <height>480</height>
            <format>R8G8B8</format>
          </image>
          <clip>
            <near>0.02</near>
            <far>300</far>
          </clip>
        </camera>
        <plugin name='gazebo_ros_depth_camera_sensor' filename='libgazebo_ros_openni_kinect.so'>
          <baseline>0.2</baseline>
          <alwaysOn>true</alwaysOn>
          <updateRate>10.0</updateRate>
          <cameraName>camera_ir</cameraName>
          <imageTopicName>/limo/color/image_raw</imageTopicName>
          <cameraInfoTopicName>/limo/color/camera_info</cameraInfoTopicName>
          <depthImageTopicName>/limo/depth/image_raw</depthImageTopicName>
          <depthImageCameraInfoTopicName>/limo/depth/camera_info</depthImageCameraInfoTopicName>
          <pointCloudTopicName>/limo/depth/points</pointCloudTopicName>
          <frameName>depth_link</frameName>
          <cameraname>depth_camera_link</cameraname>
          <pointCloudCutoff>0.5</pointCloudCutoff>
          <pointCloudCutoffMax>3.0</pointCloudCutoffMax>
          <distortionK1>0</distortionK1>
          <distortionK2>0</distortionK2>
          <distortionK3>0</distortionK3>
          <distortionT1>0</distortionT1>
          <distortionT2>0</distortionT2>
          <CxPrime>0</CxPrime>
          <Cx>0</Cx>
          <Cy>0</Cy>
          <focalLength>0</focalLength>
          <hackBaseline>0</hackBaseline>
        </plugin>
        <pose>0.084000000000000005 0 0.17999999999999999 0 0 0</pose>
      </sensor>
      <gravity>true</gravity>
      <sensor name='imu_sensor' type='imu'>
        <always_on>true</always_on>
        <update_rate>100</update_rate>
        <visualize>true</visualize>
        <topic>__default_topic__</topic>
        <plugin name='imu_plugin' filename='libgazebo_ros_imu_sensor.so'>
          <topicName>/limo/imu</topicName>
          <bodyName>imu_link</bodyName>
          <updateRateHZ>100.0</updateRateHZ>
          <gaussianNoise>0.001</gaussianNoise>
          <xyzOffset>0 0 0</xyzOffset>
          <rpyOffset>0 0 0</rpyOffset>
          <frameName>imu_link</frameName>
        </plugin>
        <pose>0 0 0.050000000000000003 0 0 0</pose>
        <imu/>
      </sensor>
      <sensor name='laser_sensor' type='ray'>
        <visualize>false</visualize>
        <update_rate>8</update_rate>
        <ray>
          <scan>
            <horizontal>
              <samples>720</samples>
              <resolution>1</resolution>
              <min_angle>-2.0943950400000002</min_angle>
              <max_angle>2.0943950400000002</max_angle>
            </horizontal>
          </scan>
          <range>
            <min>0.050000000000000003</min>
            <max>8</max>
            <resolution>0.01</resolution>
          </range>
          <noise>
            <type>gaussian</type>
            <mean>0</mean>
            <stddev>0.01</stddev>
          </noise>
        </ray>
        <plugin name='gazebo_ros_laser_sensor' filename='libgazebo_ros_ray_sensor.so'>
          <ros>
            <remapping>~/out:=scan</remapping>
          </ros>
          <topicName>/limo/scan</topicName>
          <frameName>laser_link</frameName>
        </plugin>
        <pose>0.10299999999999999 0 0.11600000000000001 0 0 0</pose>
      </sensor>
    </link>
    <joint name='left_steering_hinge_wheel' type='revolute'>
      <pose relative_to='base_footprint'>0.10000000000000001 0.070000000000000007 0.04900199999999999 0 0 0</pose>
      <parent>base_footprint</parent>
      <child>left_steering_hinge</child>
      <axis>
        <xyz>0 0 1</xyz>
        <limit>
          <lower>-0.52359876699999996</lower>
          <upper>0.52359876699999996</upper>
          <effort>5</effort>
          <velocity>0.5</velocity>
        </limit>
        <dynamics>
          <damping>1</damping>
          <friction>2</friction>
          <spring_reference>0</spring_reference>
          <spring_stiffness>0</spring_stiffness>
        </dynamics>
      </axis>
    </joint>
    <link name='left_steering_hinge'>
      <pose relative_to='left_steering_hinge_wheel'>0 0 0 0 0 0</pose>
      <inertial>
        <pose>0 0 0 0 0 0</pose>
        <mass>0.25</mass>
        <inertia>
          <ixx>0.0052500000000000003</ixx>
          <ixy>0</ixy>
          <ixz>0</ixz>
          <iyy>0.00035</iyy>
          <iyz>0</iyz>
          <izz>0.0052500000000000003</izz>
        </inertia>
      </inertial>
      <collision name='left_steering_hinge_collision'>
        <pose>0 0.022499999999999999 0 1.5700000000000001 0 0</pose>
        <geometry>
          <cylinder>
            <length>0.044999999999999998</length>
            <radius>0.035000000000000003</radius>
          </cylinder>
        </geometry>
      </collision>
      <visual name='left_steering_hinge_visual'>
        <pose>0 0 0 0 0 0</pose>
        <geometry>
          <cylinder>
            <length>0.0001</length>
            <radius>0.0001</radius>
          </cylinder>
        </geometry>
      </visual>
    </link>
    <joint name='front_left_wheel' type='revolute'>
      <pose relative_to='left_steering_hinge'>0 0 0 0 0 0</pose>
      <parent>left_steering_hinge</parent>
      <child>front_left_wheel_link</child>
      <axis>
        <xyz>0 1 0</xyz>
        <limit>
          <lower>-inf</lower>
          <upper>inf</upper>
        </limit>
        <dynamics>
          <spring_reference>0</spring_reference>
          <spring_stiffness>0</spring_stiffness>
        </dynamics>
      </axis>
    </joint>
    <link name='front_left_wheel_link'>
      <pose relative_to='front_left_wheel'>0 0 0 0 0 0</pose>
      <inertial>
        <pose>0 0 0 0 0 0</pose>
        <mass>0.25</mass>
        <inertia>
          <ixx>0.0052500000000000003</ixx>
          <ixy>0</ixy>
          <ixz>0</ixz>
          <iyy>0.00035</iyy>
          <iyz>0</iyz>
          <izz>0.0052500000000000003</izz>
        </inertia>
      </inertial>
      <collision name='front_left_wheel_link_collision'>
        <pose>0 0.022499999999999999 0 1.5700000000000001 0 0</pose>
        <geometry>
          <cylinder>
            <length>0.044999999999999998</length>
            <radius>0.044999999999999998</radius>
          </cylinder>
        </geometry>
        <surface>
          <contact>
            <ode>
              <kp>10000000</kp>
              <kd>1</kd>
              <min_depth>0.001</min_depth>
            </ode>
          </contact>
          <friction>
            <ode>
              <mu>10</mu>
              <mu2>10</mu2>
            </ode>
          </friction>
        </surface>
      </collision>
      <visual name='front_left_wheel_link_visual'>
        <pose>0 0 0 0 0 0</pose>
        <geometry>
          <mesh>
            <scale>1 1 1</scale>
            <uri>file:///home/beamkeerati/FRA532_MobileRobot/LAB1_WS/install/limo_description/share/limo_description/meshes/limo_wheel.dae</uri>
          </mesh>
        </geometry>
      </visual>
    </link>
    <joint name='rear_left_wheel' type='revolute'>
      <pose relative_to='base_footprint'>-0.10000000000000001 0.070000000000000007 0.04900199999999999 0 0 0</pose>
      <parent>base_footprint</parent>
      <child>rear_left_wheel_link</child>
      <axis>
        <xyz>0 1 0</xyz>
        <limit>
          <lower>-inf</lower>
          <upper>inf</upper>
        </limit>
        <dynamics>
          <spring_reference>0</spring_reference>
          <spring_stiffness>0</spring_stiffness>
        </dynamics>
      </axis>
    </joint>
    <link name='rear_left_wheel_link'>
      <pose relative_to='rear_left_wheel'>0 0 0 0 0 0</pose>
      <inertial>
        <pose>0 0 0 0 0 0</pose>
        <mass>0.5</mass>
        <inertia>
          <ixx>0.01055</ixx>
          <ixy>0</ixy>
          <ixz>0</ixz>
          <iyy>0.00075000000000000002</iyy>
          <iyz>0</iyz>
          <izz>0.01055</izz>
        </inertia>
      </inertial>
      <collision name='rear_left_wheel_link_collision'>
        <pose>0 0.022499999999999999 0 1.5700000000000001 0 0</pose>
        <geometry>
          <cylinder>
            <length>0.044999999999999998</length>
            <radius>0.044999999999999998</radius>
          </cylinder>
        </geometry>
      </collision>
      <visual name='rear_left_wheel_link_visual'>
        <pose>0 0 0 0 0 0</pose>
        <geometry>
          <mesh>
            <scale>1 1 1</scale>
            <uri>model://limo_description/meshes/limo_wheel.dae</uri>
          </mesh>
        </geometry>
      </visual>
    </link>
    <joint name='rear_right_wheel' type='revolute'>
      <pose relative_to='base_footprint'>-0.10000000000000001 -0.070000000000000007 0.04900199999999999 3.1415899999999999 0 0</pose>
      <parent>base_footprint</parent>
      <child>rear_right_wheel_link</child>
      <axis>
        <xyz>0 -1 0</xyz>
        <limit>
          <lower>-inf</lower>
          <upper>inf</upper>
        </limit>
        <dynamics>
          <spring_reference>0</spring_reference>
          <spring_stiffness>0</spring_stiffness>
        </dynamics>
      </axis>
    </joint>
    <link name='rear_right_wheel_link'>
      <pose relative_to='rear_right_wheel'>0 0 0 0 0 0</pose>
      <inertial>
        <pose>0 0 0 0 0 0</pose>
        <mass>0.5</mass>
        <inertia>
          <ixx>0.01055</ixx>
          <ixy>0</ixy>
          <ixz>0</ixz>
          <iyy>0.00075000000000000002</iyy>
          <iyz>0</iyz>
          <izz>0.01055</izz>
        </inertia>
      </inertial>
      <collision name='rear_right_wheel_link_collision'>
        <pose>0 0.022499999999999999 0 1.5700000000000001 0 0</pose>
        <geometry>
          <cylinder>
            <length>0.044999999999999998</length>
            <radius>0.044999999999999998</radius>
          </cylinder>
        </geometry>
      </collision>
      <visual name='rear_right_wheel_link_visual'>
        <pose>0 0 0 0 0 0</pose>
        <geometry>
          <mesh>
            <scale>1 1 1</scale>
            <uri>model://limo_description/meshes/limo_wheel.dae</uri>
          </mesh>
        </geometry>
      </visual>
    </link>
    <joint name='right_steering_hinge_wheel' type='revolute'>
      <pose relative_to='base_footprint'>0.10000000000000001 -0.070000000000000007 0.04900199999999999 3.1415899999999999 0 0</pose>
      <parent>base_footprint</parent>
      <child>right_steering_hinge</child>
      <axis>
        <xyz>0 0 -1</xyz>
        <limit>
          <lower>-0.52359876699999996</lower>
          <upper>0.52359876699999996</upper>
          <effort>5</effort>
          <velocity>0.5</velocity>
        </limit>
        <dynamics>
          <damping>1</damping>
          <friction>2</friction>
          <spring_reference>0</spring_reference>
          <spring_stiffness>0</spring_stiffness>
        </dynamics>
      </axis>
    </joint>
    <link name='right_steering_hinge'>
      <pose relative_to='right_steering_hinge_wheel'>0 0 0 0 0 0</pose>
      <inertial>
        <pose>0 0 0 0 0 0</pose>
        <mass>0.25</mass>
        <inertia>
          <ixx>0.0052500000000000003</ixx>
          <ixy>0</ixy>
          <ixz>0</ixz>
          <iyy>0.00035</iyy>
          <iyz>0</iyz>
          <izz>0.0052500000000000003</izz>
        </inertia>
      </inertial>
      <collision name='right_steering_hinge_collision'>
        <pose>0 0.022499999999999999 0 1.5700000000000001 0 0</pose>
        <geometry>
          <cylinder>
            <length>0.044999999999999998</length>
            <radius>0.035000000000000003</radius>
          </cylinder>
        </geometry>
      </collision>
      <visual name='right_steering_hinge_visual'>
        <pose>0 0 0 0 0 0</pose>
        <geometry>
          <cylinder>
            <length>0.0001</length>
            <radius>0.0001</radius>
          </cylinder>
        </geometry>
      </visual>
    </link>
    <joint name='front_right_wheel' type='revolute'>
      <pose relative_to='right_steering_hinge'>0 0 0 0 0 0</pose>
      <parent>right_steering_hinge</parent>
      <child>front_right_wheel_link</child>
      <axis>
        <xyz>0 -1 0</xyz>
        <limit>
          <lower>-inf</lower>
          <upper>inf</upper>
        </limit>
        <dynamics>
          <spring_reference>0</spring_reference>
          <spring_stiffness>0</spring_stiffness>
        </dynamics>
      </axis>
    </joint>
    <link name='front_right_wheel_link'>
      <pose relative_to='front_right_wheel'>0 0 0 0 0 0</pose>
      <inertial>
        <pose>0 0 0 0 0 0</pose>
        <mass>0.25</mass>
        <inertia>
          <ixx>0.0052500000000000003</ixx>
          <ixy>0</ixy>
          <ixz>0</ixz>
          <iyy>0.00035</iyy>
          <iyz>0</iyz>
          <izz>0.0052500000000000003</izz>
        </inertia>
      </inertial>
      <collision name='front_right_wheel_link_collision'>
        <pose>0 0.022499999999999999 0 1.5700000000000001 0 0</pose>
        <geometry>
          <cylinder>
            <length>0.044999999999999998</length>
            <radius>0.044999999999999998</radius>
          </cylinder>
        </geometry>
        <surface>
          <contact>
            <ode>
              <kp>1000000</kp>
              <kd>1</kd>
              <min_depth>0.001</min_depth>
            </ode>
          </contact>
          <friction>
            <ode>
              <mu>10</mu>
              <mu2>10</mu2>
            </ode>
          </friction>
        </surface>
      </collision>
      <visual name='front_right_wheel_link_visual'>
        <pose>0 0 0 0 0 0</pose>
        <geometry>
          <mesh>
            <scale>1 1 1</scale>
            <uri>file:///home/beamkeerati/FRA532_MobileRobot/LAB1_WS/install/limo_description/share/limo_description/meshes/limo_wheel.dae</uri>
          </mesh>
        </geometry>
      </visual>
    </link>
    <plugin name='gazebo_ros2_control' filename='libgazebo_ros2_control.so'>
      <parameters>/home/beamkeerati/FRA532_MobileRobot/LAB1_WS/install/limo_description/share/limo_description/config/limo_controller.yaml</parameters>
    </plugin>
    <plugin name='ground_truth_plugin' filename='libgazebo_ros_p3d.so'>
      <ros>
        <remapping>odom:=/odometry/ground_truth</remapping>
      </ros>
      <frameName>world</frameName>
      <body_name>base_footprint</body_name>
      <updateRate>100.0</updateRate>
    </plugin>
    <frame name='depth_camera_to_camera_joint' attached_to='depth_camera_link'>
      <pose>0 0 0 -1.5707949999999999 -5.5511151231257827e-17 -1.5707949999999999</pose>
    </frame>
    <frame name='depth_link' attached_to='depth_camera_to_camera_joint'>
      <pose>0 0 0 0 0 0</pose>
    </frame>
    <frame name='depth_camera_joint' attached_to='base_link'>
      <pose>0.084000000000000005 0 0.029999999999999999 0 0 0</pose>
    </frame>
    <frame name='depth_camera_link' attached_to='depth_camera_joint'>
      <pose>0 0 0 0 0 0</pose>
    </frame>
    <frame name='imu_joint' attached_to='base_link'>
      <pose>0 0 -0.10000000000000001 0 0 0</pose>
    </frame>
    <frame name='imu_link' attached_to='imu_joint'>
      <pose>0 0 0 0 0 0</pose>
    </frame>
    <frame name='inertial_joint' attached_to='base_link'>
      <pose>0 0 0 0 0 0</pose>
    </frame>
    <frame name='inertial_link' attached_to='inertial_joint'>
      <pose>0 0 0 0 0 0</pose>
    </frame>
    <frame name='laser_joint' attached_to='base_link'>
      <pose>0.10299999999999999 0 -0.034000000000000002 0 0 0</pose>
    </frame>
    <frame name='laser_link' attached_to='laser_joint'>
      <pose>0 0 0 0 0 0</pose>
    </frame>
    <frame name='base_joint' attached_to='base_footprint'>
      <pose>0 0 0.14999999999999999 0 0 0</pose>
    </frame>
    <frame name='base_link' attached_to='base_joint'>
      <pose>0 0 0 0 0 0</pose>
    </frame>
  </model>
</sdf>
